[2024-11-23T17:18:20.676+0000] {local_task_job_runner.py:123} INFO - ::group::Pre task execution logs
[2024-11-23T17:18:20.759+0000] {taskinstance.py:2612} INFO - Dependencies all met for dep_context=non-requeueable deps ti=<TaskInstance: fraud_detection.log_to_mlflow scheduled__2024-11-23T17:16:00+00:00 [queued]>
[2024-11-23T17:18:20.816+0000] {taskinstance.py:2612} INFO - Dependencies all met for dep_context=requeueable deps ti=<TaskInstance: fraud_detection.log_to_mlflow scheduled__2024-11-23T17:16:00+00:00 [queued]>
[2024-11-23T17:18:20.825+0000] {taskinstance.py:2865} INFO - Starting attempt 1 of 2
[2024-11-23T17:18:20.889+0000] {taskinstance.py:2888} INFO - Executing <Task(PythonOperator): log_to_mlflow> on 2024-11-23 17:16:00+00:00
[2024-11-23T17:18:20.967+0000] {warnings.py:112} WARNING - /home/***/.local/lib/python3.12/site-packages/***/task/task_runner/standard_task_runner.py:70: DeprecationWarning: This process (pid=1965) is multi-threaded, use of fork() may lead to deadlocks in the child.
  pid = os.fork()

[2024-11-23T17:18:20.976+0000] {standard_task_runner.py:72} INFO - Started process 1970 to run task
[2024-11-23T17:18:20.978+0000] {standard_task_runner.py:104} INFO - Running: ['***', 'tasks', 'run', 'fraud_detection', 'log_to_mlflow', 'scheduled__2024-11-23T17:16:00+00:00', '--job-id', '196', '--raw', '--subdir', 'DAGS_FOLDER/fraud_detection_dag.py', '--cfg-path', '/tmp/tmp_hvxek5a']
[2024-11-23T17:18:20.987+0000] {standard_task_runner.py:105} INFO - Job 196: Subtask log_to_mlflow
[2024-11-23T17:18:21.169+0000] {task_command.py:467} INFO - Running <TaskInstance: fraud_detection.log_to_mlflow scheduled__2024-11-23T17:16:00+00:00 [running]> on host 345e92ff26bf
[2024-11-23T17:18:21.353+0000] {taskinstance.py:3131} INFO - Exporting env vars: AIRFLOW_CTX_DAG_OWNER='fraud_team' AIRFLOW_CTX_DAG_ID='fraud_detection' AIRFLOW_CTX_TASK_ID='log_to_mlflow' AIRFLOW_CTX_EXECUTION_DATE='2024-11-23T17:16:00+00:00' AIRFLOW_CTX_TRY_NUMBER='1' AIRFLOW_CTX_DAG_RUN_ID='scheduled__2024-11-23T17:16:00+00:00'
[2024-11-23T17:18:21.356+0000] {taskinstance.py:731} INFO - ::endgroup::
[2024-11-23T17:18:25.237+0000] {fraud_detection_dag.py:409} INFO - Expérience existante utilisée : fraud_detection_pipeline (ID: 1)
[2024-11-23T17:18:25.419+0000] {logging_mixin.py:190} WARNING - 2024/11/23 17:18:25 WARNING mlflow.utils.git_utils: Failed to import Git (the Git executable is probably not on your PATH), so Git SHA is not available. Error: Failed to initialize: Bad git executable.
The git executable must be specified in one of the following ways:
    - be included in your $PATH
    - be set via $GIT_PYTHON_GIT_EXECUTABLE
    - explicitly set via git.refresh(<full-path-to-git-executable>)

All git commands will error until this is rectified.

This initial message can be silenced or aggravated in the future by setting the
$GIT_PYTHON_REFRESH environment variable. Use one of the following values:
    - quiet|q|silence|s|silent|none|n|0: for no message or exception
    - warn|w|warning|log|l|1: for a warning message (logging level CRITICAL, displayed by default)
    - error|e|exception|raise|r|2: for a raised exception

Example:
    export GIT_PYTHON_REFRESH=quiet
[2024-11-23T17:18:47.555+0000] {credentials.py:1147} INFO - Found credentials in environment variables.
[2024-11-23T17:19:26.209+0000] {python.py:240} INFO - Done. Returned value was: None
[2024-11-23T17:19:26.322+0000] {taskinstance.py:340} INFO - ::group::Post task execution logs
[2024-11-23T17:19:26.329+0000] {taskinstance.py:352} INFO - Marking task as SUCCESS. dag_id=fraud_detection, task_id=log_to_mlflow, run_id=scheduled__2024-11-23T17:16:00+00:00, execution_date=20241123T171600, start_date=20241123T171820, end_date=20241123T171926
[2024-11-23T17:19:26.396+0000] {local_task_job_runner.py:266} INFO - Task exited with return code 0
[2024-11-23T17:19:26.452+0000] {taskinstance.py:3900} INFO - 0 downstream tasks scheduled from follow-on schedule check
[2024-11-23T17:19:26.464+0000] {local_task_job_runner.py:245} INFO - ::endgroup::
[2024-11-23T17:19:26.533+0000] {standard_task_runner.py:217} INFO - Process not found (most likely exited), stop collecting metrics
